File: example_files/03252015_1DC_100OS_140MPa_02_19 NEES.txt
Test name: 03252015_1DC_100OS_140MPa_02_19
Test author: AMP
Material: Ottawa sand F-65
Soil batch delivered to: UCDavis CGM
Soil batch delivery date: 05/2014
Gs 2.65
High pressure consolidation phase
Vertical E. Stress Void Ratio Vertical Strains
(MPa)   (-)     (-)
0.10000 0.72673 0.00000
0.32800 0.72592 0.00047
0.38230 0.72551 0.00071
0.47281 0.72510 0.00095
0.49091 0.72265 0.00236
0.58141 0.72347 0.00189
0.61761 0.72143 0.00307
0.69001 0.71898 0.00449
0.79861 0.72224 0.00260
0.81671 0.71898 0.00449
0.61399 0.72225 0.00260
0.68096 0.72123 0.00319
0.74793 0.72021 0.00378
0.82938 0.71923 0.00435
0.91626 0.71857 0.00472
0.99953 0.71768 0.00524
1.09003 0.71666 0.00583
1.19682 0.71596 0.00624
1.30180 0.71486 0.00687
1.41583 0.71388 0.00744
1.53530 0.71319 0.00784
1.65114 0.71242 0.00829
1.78870 0.71156 0.00879
1.91902 0.71066 0.00931
2.05659 0.70976 0.00983
2.20682 0.70878 0.01039
2.36610 0.70817 0.01075
2.52177 0.70736 0.01122
2.68648 0.70654 0.01169
2.85662 0.70560 0.01224
3.01953 0.70483 0.01269
3.20053 0.70389 0.01323
3.37430 0.70295 0.01377
3.55892 0.70218 0.01422
3.74536 0.70099 0.01491
3.93722 0.69993 0.01552
4.13452 0.69871 0.01623
4.33181 0.69769 0.01682
4.53816 0.69659 0.01746
4.74450 0.69589 0.01786
4.97076 0.69459 0.01861
5.19701 0.69353 0.01923
5.43231 0.69267 0.01972
5.66400 0.69157 0.02036
5.90292 0.69071 0.02086
6.13461 0.68986 0.02136
6.38077 0.68916 0.02176
6.62151 0.68823 0.02230
6.85682 0.68737 0.02280
7.10479 0.68602 0.02358
7.35096 0.68541 0.02393
7.60617 0.68480 0.02428
7.85415 0.68386 0.02483
8.11841 0.68309 0.02528
8.38811 0.68227 0.02575
8.65600 0.68145 0.02622
8.90578 0.68052 0.02677
9.17548 0.67962 0.02728
9.45241 0.67876 0.02778
9.73297 0.67811 0.02816
10.00085 0.67676 0.02894
10.28322 0.67570 0.02955
10.56739 0.67489 0.03003
10.82804 0.67419 0.03043
11.09231 0.67321 0.03099
11.37648 0.67228 0.03154
11.66247 0.67117 0.03217
11.94122 0.67028 0.03269
12.22539 0.66975 0.03300
12.50414 0.66897 0.03345
12.79555 0.66816 0.03392
13.07611 0.66710 0.03454
13.36571 0.66604 0.03515
13.66255 0.66469 0.03593
13.94673 0.66363 0.03655
14.23634 0.66249 0.03721
14.52775 0.66171 0.03766
14.82097 0.66085 0.03815
15.09791 0.65959 0.03888
15.38571 0.65865 0.03943
15.66084 0.65779 0.03992
15.93958 0.65710 0.04033
16.20927 0.65612 0.04089
16.49164 0.65514 0.04146
16.77944 0.65433 0.04193
17.05094 0.65351 0.04240
17.32787 0.65327 0.04255
17.60480 0.65237 0.04307
17.89621 0.65135 0.04366
18.17314 0.65033 0.04425
18.45009 0.64943 0.04477
18.73246 0.64845 0.04533
19.00578 0.64776 0.04573
19.27548 0.64703 0.04616
19.55241 0.64609 0.04670
19.82754 0.64523 0.04720
20.09181 0.64352 0.04819
20.35789 0.64262 0.04871
20.62034 0.64180 0.04918
20.88823 0.64066 0.04985
21.16336 0.63985 0.05032
21.43305 0.63891 0.05086
21.71722 0.63760 0.05162
21.98691 0.63679 0.05209
22.24575 0.63573 0.05270
22.51726 0.63463 0.05334
22.80144 0.63389 0.05377
23.06752 0.63295 0.05431
23.33721 0.63189 0.05492
23.60329 0.63132 0.05526
23.86755 0.63006 0.05599
24.11734 0.62916 0.05651
24.37074 0.62851 0.05689
24.63319 0.62757 0.05743
24.89384 0.62692 0.05781
25.14001 0.62634 0.05814
25.38617 0.62549 0.05863
25.64320 0.62422 0.05937
25.89119 0.62292 0.06012
26.14640 0.62186 0.06074
26.39800 0.62129 0.06107
26.65140 0.62014 0.06173
26.89939 0.61904 0.06237
27.15099 0.61798 0.06298
27.39896 0.61680 0.06366
27.65056 0.61582 0.06423
27.89131 0.61456 0.06496
28.14471 0.61390 0.06534
28.39088 0.61321 0.06574
28.62799 0.61239 0.06622
28.87055 0.61093 0.06707
29.08775 0.61007 0.06756
29.31039 0.60921 0.06806
29.51674 0.60819 0.06865
29.74662 0.60742 0.06910
29.97648 0.60615 0.06983
30.19911 0.60509 0.07044
30.41088 0.60375 0.07122
30.63170 0.60260 0.07189
30.84890 0.60114 0.07274
31.06972 0.60024 0.07326
31.31951 0.59914 0.07389
31.56386 0.59832 0.07437
31.79372 0.59718 0.07503
32.01636 0.59591 0.07576
32.24262 0.59510 0.07623
32.48518 0.59445 0.07661
32.71143 0.59302 0.07744
32.94311 0.59204 0.07800
33.17480 0.59102 0.07860
33.40105 0.59029 0.07902
33.61825 0.58939 0.07954
33.84270 0.58812 0.08027
34.08344 0.58719 0.08082
34.31513 0.58617 0.08141
34.53957 0.58510 0.08202
34.75497 0.58372 0.08282
34.97941 0.58323 0.08311
35.19844 0.58249 0.08353
35.41927 0.58168 0.08400
35.64010 0.58041 0.08474
35.87721 0.57939 0.08533
36.08717 0.57801 0.08613
36.30438 0.57674 0.08686
36.52519 0.57568 0.08748
36.75688 0.57470 0.08804
36.97770 0.57381 0.08856
37.20938 0.57274 0.08918
37.44468 0.57168 0.08979
37.66912 0.57071 0.09036
37.89176 0.56969 0.09095
38.11803 0.56867 0.09154
38.34791 0.56793 0.09197
38.57235 0.56728 0.09234
38.79499 0.56654 0.09277
38.99952 0.56536 0.09345
39.22216 0.56418 0.09414
39.43212 0.56328 0.09466
39.64209 0.56185 0.09549
39.86471 0.56092 0.09603
40.08916 0.55981 0.09667
40.28101 0.55871 0.09730
40.50184 0.55765 0.09792
40.71723 0.55647 0.09860
40.92900 0.55524 0.09931
41.14982 0.55418 0.09993
41.36521 0.55333 0.10042
41.59329 0.55272 0.10078
41.81230 0.55190 0.10125
42.03494 0.55076 0.10191
42.24490 0.54978 0.10248
42.47478 0.54876 0.10307
42.67931 0.54770 0.10368
42.90375 0.54664 0.10430
43.12639 0.54554 0.10494
43.35266 0.54460 0.10548
43.57891 0.54370 0.10600
43.79249 0.54219 0.10687
44.00245 0.54146 0.10730
44.20698 0.54044 0.10789
44.43143 0.53974 0.10829
44.64863 0.53873 0.10888
44.87851 0.53791 0.10935
45.09753 0.53750 0.10959
45.31654 0.53648 0.11018
45.53012 0.53518 0.11094
45.75637 0.53379 0.11174
45.98262 0.53265 0.11240
46.21794 0.53142 0.11311
46.45868 0.53032 0.11375
46.67950 0.52902 0.11450
46.91480 0.52787 0.11516
47.14648 0.52694 0.11571
47.37817 0.52551 0.11653
47.60985 0.52461 0.11705
47.83973 0.52367 0.11760
48.05513 0.52282 0.11809
48.27777 0.52159 0.11880
48.50765 0.51992 0.11977
48.72846 0.51878 0.12043
48.94929 0.51764 0.12109
49.17193 0.51649 0.12176
49.38914 0.51502 0.12261
49.62263 0.51360 0.12343
49.86337 0.51246 0.12409
50.08601 0.51135 0.12473
50.32494 0.51066 0.12513
50.55843 0.50997 0.12553
50.77381 0.50944 0.12584
51.01093 0.50878 0.12622
51.25890 0.50776 0.12681
51.49239 0.50683 0.12735
51.73674 0.50609 0.12778
51.96118 0.50511 0.12835
52.19287 0.50417 0.12889
52.45169 0.50340 0.12934
52.68518 0.50193 0.13019
52.92411 0.50071 0.13090
53.17210 0.49981 0.13142
53.41102 0.49838 0.13224
53.65356 0.49757 0.13272
53.90696 0.49679 0.13317
54.16219 0.49569 0.13380
54.40111 0.49491 0.13425
54.64546 0.49406 0.13475
54.87896 0.49320 0.13524
55.12876 0.49247 0.13567
55.38216 0.49169 0.13612
55.64281 0.49051 0.13680
55.89983 0.48969 0.13728
56.16047 0.48925 0.13754
56.41388 0.48794 0.13829
56.65461 0.48692 0.13888
56.92430 0.48578 0.13954
57.18495 0.48447 0.14030
57.45101 0.48329 0.14098
57.70984 0.48215 0.14165
57.98135 0.48101 0.14231
58.23837 0.47966 0.14309
58.50083 0.47860 0.14370
58.75787 0.47693 0.14467
59.01309 0.47595 0.14524
59.28641 0.47521 0.14566
59.54886 0.47423 0.14623
59.82038 0.47334 0.14675
60.08102 0.47219 0.14741
60.36158 0.47113 0.14802
60.62403 0.46999 0.14869
60.90279 0.46942 0.14902
61.15619 0.46844 0.14958
61.42951 0.46750 0.15013
61.72273 0.46677 0.15055
61.99605 0.46534 0.15138
62.27480 0.46428 0.15199
62.53725 0.46330 0.15256
62.82868 0.46265 0.15294
63.10019 0.46200 0.15332
63.38438 0.46126 0.15374
63.67218 0.46024 0.15433
63.97627 0.45910 0.15499
64.26407 0.45820 0.15551
64.53195 0.45710 0.15615
64.81793 0.45624 0.15665
65.12021 0.45551 0.15707
65.42249 0.45445 0.15769
65.72477 0.45331 0.15835
66.02523 0.45241 0.15887
66.31664 0.45139 0.15946
66.60625 0.45041 0.16002
66.91033 0.44960 0.16050
67.21442 0.44825 0.16128
67.51489 0.44756 0.16168
67.83346 0.44682 0.16210
68.13211 0.44576 0.16272
68.44344 0.44486 0.16324
68.74390 0.44380 0.16385
69.06790 0.44246 0.16463
69.38827 0.44144 0.16522
69.70140 0.44078 0.16560
70.00549 0.44005 0.16603
70.31319 0.43944 0.16638
70.67157 0.43830 0.16704
70.98290 0.43715 0.16770
71.30509 0.43634 0.16818
71.61281 0.43544 0.16869
71.92957 0.43426 0.16938
72.24633 0.43324 0.16997
72.58118 0.43246 0.17042
72.89975 0.43124 0.17113
73.22555 0.43006 0.17181
73.56765 0.42912 0.17236
73.85907 0.42798 0.17302
74.19755 0.42700 0.17359
74.53241 0.42602 0.17415
74.87811 0.42504 0.17472
75.22564 0.42414 0.17524
75.56954 0.42341 0.17566
75.88811 0.42251 0.17618
76.25736 0.42186 0.17656
76.61756 0.42096 0.17708
76.96147 0.42006 0.17760
77.33253 0.41945 0.17796
77.67825 0.41872 0.17838
78.03663 0.41770 0.17897
78.40226 0.41680 0.17949
78.75703 0.41590 0.18001
79.11180 0.41472 0.18070
79.48104 0.41345 0.18143
79.82133 0.41239 0.18204
80.17428 0.41150 0.18256
80.54172 0.41052 0.18313
80.91097 0.40938 0.18379
81.27478 0.40836 0.18438
81.63318 0.40734 0.18497
81.98975 0.40595 0.18577
82.36443 0.40542 0.18608
82.73187 0.40473 0.18648
83.11742 0.40403 0.18688
83.50658 0.40313 0.18740
83.89937 0.40248 0.18778
84.29758 0.40162 0.18828
84.67768 0.40073 0.18880
85.07770 0.39991 0.18927
85.47228 0.39914 0.18972
85.86868 0.39873 0.18996
86.26326 0.39746 0.19069
86.66690 0.39665 0.19116
87.05063 0.39583 0.19163
87.45064 0.39498 0.19213
87.84703 0.39424 0.19255
88.22170 0.39359 0.19293
88.61810 0.39265 0.19348
89.01450 0.39171 0.19402
89.41995 0.39082 0.19454
89.82540 0.38988 0.19508
90.23990 0.38927 0.19544
90.64534 0.38833 0.19598
91.05621 0.38731 0.19657
91.45985 0.38641 0.19709
91.88160 0.38535 0.19770
92.30697 0.38417 0.19839
92.71785 0.38315 0.19898
93.13234 0.38249 0.19936
93.54866 0.38172 0.19981
93.96315 0.38094 0.20026
94.37042 0.38025 0.20066
94.79579 0.37960 0.20104
95.22478 0.37882 0.20148
95.64651 0.37805 0.20193
96.05377 0.37703 0.20252
96.47550 0.37638 0.20290
96.91352 0.37580 0.20323
97.34613 0.37491 0.20375
97.78053 0.37401 0.20427
98.22038 0.37323 0.20472
98.65659 0.37262 0.20507
99.08920 0.37201 0.20543
99.53446 0.37144 0.20576
99.98335 0.37083 0.20611
100.43400 0.37060 0.20635
100.87200 0.36940 0.20692
101.31370 0.36890 0.20722
101.76260 0.36860 0.20737
102.20420 0.36790 0.20777
102.65310 0.36720 0.20819
103.09840 0.36600 0.20890
103.56180 0.36480 0.20959
103.99800 0.36380 0.21018
104.44690 0.36290 0.21070
104.89940 0.36180 0.21129
105.36820 0.36180 0.21134
105.82070 0.36100 0.21176
106.27680 0.35990 0.21240
106.75110 0.35890 0.21299
107.21810 0.35810 0.21344
107.69050 0.35740 0.21384
108.14300 0.35670 0.21429
108.64620 0.35610 0.21464
109.12220 0.35560  0.21488
109.59460 0.35500  0.21526
110.07430 0.35370  0.21599
110.56840 0.35280  0.21651
111.06260 0.35170  0.21715
111.55130 0.35110  0.21752
112.04720 0.35040  0.21793
112.55400 0.34970  0.21833
113.06080 0.34900  0.21873
113.56040 0.34810  0.21925
114.04550 0.34640  0.22022
114.54330 0.34520  0.22090
115.05550 0.34440  0.22138
115.56230 0.34360  0.22185
116.03840 0.34320  0.22206
116.54880 0.34250  0.22251
117.03750 0.34180  0.22289
117.52980 0.34110  0.22329
118.00950 0.34070  0.22355
118.48190 0.34010  0.22390
119.00140 0.34000  0.22395
119.51360 0.33930  0.22433
119.98790 0.33860  0.22475
120.46390 0.33810  0.22501
120.97800 0.33720  0.22558
121.44860 0.33660  0.22593
121.95180 0.33550  0.22653
122.45310 0.33490  0.22690
122.97260 0.33410  0.22738
123.46490 0.33340  0.22778
123.95910 0.33270  0.22816
124.45140 0.33240  0.22837
124.96000 0.33190  0.22863
125.46690 0.33110  0.22910
125.97550 0.33050  0.22943
126.49130 0.33010  0.22969
127.00720 0.32970  0.22990
127.50310 0.32910  0.23026
128.00820 0.32800  0.23092
128.53850 0.32750  0.23116
129.03990 0.32670  0.23163
129.55030 0.32600  0.23208
130.06620 0.32540  0.23238
130.57660 0.32490  0.23271
133.40210 0.32040  0.23529
133.96320 0.32160  0.23458
134.39760 0.31920  0.23600
134.97680 0.31840  0.23647
135.42930 0.31920  0.23600
135.95420 0.31670  0.23742
136.58770 0.31920  0.23600
137.07650 0.31840  0.23647
137.58330 0.31710  0.23718
138.12620 0.31470  0.23860
138.63310 0.31670  0.23742