File: example_files/03302015_1DC_100OS_70MPA_01_22 NEES.txt
Test name: 03302015_1DC_100OS_70MPA_01_22
Test author: AMP
Material: Ottawa sand F-65
Soil batch delivered to: UCDavis CGM
Soil batch delivery date: 05/2014
Gs 2.65
High pressure consolidation phase
Vertical E. Stress Void Ratio Vertical Strains
(MPa)   (-)     (-)
0.10000 0.73536 0.00000
0.26628 0.73368 0.00097
0.32058 0.73117 0.00241
0.35678 0.73368 0.00097
0.37489 0.73242 0.00169
0.39299 0.72907 0.00362
0.50159 0.72991 0.00314
0.51969 0.72740 0.00459
0.51969 0.72572 0.00555
0.68259 0.72698 0.00483
0.45996 0.72941 0.00343
0.50883 0.72869 0.00384
0.56494 0.72786 0.00432
0.61743 0.72681 0.00493
0.68259 0.72585 0.00548
0.75318 0.72501 0.00596
0.82740 0.72400 0.00654
0.90704 0.72358 0.00678
1.00297 0.72304 0.00710
1.09709 0.72203 0.00768
1.20207 0.72136 0.00806
1.31611 0.72036 0.00864
1.42471 0.71964 0.00905
1.54598 0.71855 0.00968
1.66906 0.71759 0.01024
1.80301 0.71692 0.01062
1.94057 0.71592 0.01120
2.08356 0.71478 0.01186
2.23560 0.71357 0.01256
2.38765 0.71260 0.01311
2.53969 0.71147 0.01376
2.70440 0.71055 0.01429
2.87455 0.70963 0.01483
3.05193 0.70879 0.01531
3.24017 0.70804 0.01574
3.43204 0.70703 0.01632
3.61666 0.70615 0.01683
3.82120 0.70506 0.01746
4.02030 0.70410 0.01801
4.22484 0.70309 0.01859
4.44204 0.70226 0.01907
4.65563 0.70129 0.01963
4.88007 0.69999 0.02038
5.10995 0.69895 0.02098
5.33439 0.69773 0.02168
5.57513 0.69664 0.02231
5.82491 0.69597 0.02270
6.07108 0.69517 0.02316
6.32086 0.69413 0.02376
6.57789 0.69337 0.02419
6.83673 0.69249 0.02470
7.10461 0.69153 0.02526
7.37250 0.69073 0.02571
7.64581 0.68994 0.02617
7.92094 0.68893 0.02675
8.18159 0.68793 0.02733
8.45490 0.68696 0.02789
8.74089 0.68617 0.02835
9.02868 0.68533 0.02883
9.31467 0.68441 0.02936
9.61152 0.68357 0.02984
9.90112 0.68273 0.03033
10.19435 0.68202 0.03074
10.48577 0.68126 0.03117
10.77899 0.68043 0.03165
11.09032 0.67963 0.03211
11.39079 0.67862 0.03269
11.68039 0.67762 0.03327
11.97724 0.67712 0.03356
12.28133 0.67640 0.03397
12.58180 0.67548 0.03450
12.88588 0.67452 0.03506
13.19359 0.67364 0.03557
13.49767 0.67238 0.03629
13.80538 0.67188 0.03658
14.10404 0.67075 0.03723
14.41536 0.66953 0.03793
14.72849 0.66844 0.03856
15.03801 0.66702 0.03938
15.34391 0.66572 0.04013
15.65161 0.66446 0.04085
15.95389 0.66362 0.04134
16.25978 0.66237 0.04206
16.57654 0.66170 0.04245
16.88425 0.66027 0.04327
17.19376 0.65948 0.04373
17.50328 0.65885 0.04409
17.81098 0.65776 0.04472
18.11868 0.65751 0.04486
18.43181 0.65679 0.04527
18.74133 0.65646 0.04546
19.04723 0.65529 0.04614
19.34768 0.65462 0.04653
19.64453 0.65353 0.04715
19.95766 0.65244 0.04778
20.26175 0.65160 0.04827
20.56403 0.65064 0.04882
20.86994 0.64980 0.04930
21.17041 0.64829 0.05017
21.46906 0.64733 0.05073
21.76410 0.64611 0.05143
22.08086 0.64523 0.05194
22.38677 0.64427 0.05249
22.67818 0.64364 0.05285
22.97140 0.64297 0.05324
23.27007 0.64205 0.05377
23.56511 0.64104 0.05435
23.84565 0.63999 0.05495
24.14974 0.63924 0.05539
24.44659 0.63836 0.05590
24.73258 0.63723 0.05655
25.00590 0.63618 0.05715
25.29550 0.63459 0.05807
25.59235 0.63354 0.05867
25.87291 0.63258 0.05923
26.15708 0.63145 0.05988
26.44669 0.63027 0.06055
26.73268 0.62939 0.06106
27.00237 0.62847 0.06159
27.27569 0.62734 0.06225
27.56348 0.62654 0.06270
27.84223 0.62566 0.06321
28.11555 0.62516 0.06350
28.39068 0.62411 0.06410
28.67667 0.62327 0.06459
28.95180 0.62256 0.06500
29.21788 0.62185 0.06541
29.49843 0.62089 0.06596
29.77356 0.61971 0.06664
30.04327 0.61917 0.06695
30.31297 0.61820 0.06751
30.59352 0.61728 0.06804
30.86682 0.61649 0.06850
31.13653 0.61561 0.06901
31.39898 0.61448 0.06966
31.66867 0.61334 0.07031
31.92750 0.61213 0.07101
32.18271 0.61125 0.07152
32.43974 0.61020 0.07212
32.70763 0.60853 0.07309
32.95560 0.60748 0.07369
33.19815 0.60631 0.07437
33.44614 0.60555 0.07480
33.69954 0.60442 0.07545
33.95295 0.60371 0.07586
34.19731 0.60237 0.07664
34.45615 0.60115 0.07734
34.70955 0.59977 0.07813
34.95752 0.59893 0.07862
35.20369 0.59822 0.07903
35.46253 0.59688 0.07980
35.70507 0.59608 0.08026
35.95665 0.59474 0.08103
36.20099 0.59348 0.08175
36.44716 0.59223 0.08248
36.68428 0.59122 0.08306
36.92683 0.59051 0.08347
37.17119 0.58929 0.08417
37.42098 0.58829 0.08475
37.65628 0.58707 0.08545
37.89882 0.58607 0.08603
38.14861 0.58452 0.08692
38.38029 0.58343 0.08755
38.61561 0.58234 0.08818
38.85092 0.58054 0.08922
39.10252 0.57957 0.08977
39.33782 0.57853 0.09037
39.58035 0.57769 0.09086
39.82108 0.57643 0.09158
40.05096 0.57534 0.09221
40.28445 0.57438 0.09276
40.52338 0.57341 0.09332
40.76593 0.57237 0.09392
41.00123 0.57203 0.09412
41.23291 0.57165 0.09433
41.46278 0.57065 0.09491
41.69627 0.56939 0.09564
41.91347 0.56839 0.09622
42.13973 0.56721 0.09689
42.38226 0.56625 0.09745
42.60671 0.56524 0.09803
42.82935 0.56449 0.09846
43.05740 0.56348 0.09904
43.29452 0.56131 0.10030
43.52077 0.56022 0.10092
43.75065 0.55896 0.10165
43.97872 0.55787 0.10228
44.21584 0.55703 0.10276
44.43848 0.55628 0.10319
44.66655 0.55510 0.10387
44.90730 0.55406 0.10447
45.14622 0.55301 0.10508
45.38334 0.55192 0.10571
45.60959 0.55121 0.10612
45.84671 0.55029 0.10665
46.06754 0.54953 0.10708
46.29560 0.54865 0.10759
46.52729 0.54739 0.10831
46.76078 0.54597 0.10913
46.99066 0.54526 0.10954
47.21871 0.54425 0.11012
47.44316 0.54308 0.11080
47.66941 0.54228 0.11126
47.89567 0.54115 0.11191
48.13097 0.53977 0.11271
48.37351 0.53847 0.11346
48.61244 0.53755 0.11399
48.84775 0.53654 0.11457
49.08848 0.53583 0.11498
49.32016 0.53436 0.11582
49.55185 0.53315 0.11652
49.79077 0.53227 0.11703
50.02428 0.53080 0.11787
50.26138 0.52984 0.11843
50.49126 0.52879 0.11903
50.72838 0.52770 0.11966
50.97455 0.52665 0.12026
51.20441 0.52565 0.12084
51.43972 0.52439 0.12157
51.68226 0.52339 0.12215
51.93023 0.52234 0.12275
52.16553 0.52096 0.12355
52.41531 0.51974 0.12425
52.66510 0.51874 0.12483
52.91307 0.51790 0.12531
53.15200 0.51681 0.12594
53.38550 0.51580 0.12652
53.63891 0.51442 0.12731
53.87964 0.51316 0.12804
54.12580 0.51237 0.12850
54.36836 0.51111 0.12922
54.62539 0.51010 0.12980
54.86612 0.50901 0.13043
55.11590 0.50801 0.13101
55.37293 0.50684 0.13169
55.63901 0.50566 0.13236
55.89603 0.50491 0.13280
56.14943 0.50399 0.13333
56.41189 0.50294 0.13393
56.66168 0.50156 0.13473
56.90965 0.50051 0.13533
57.15399 0.49938 0.13598
57.41464 0.49862 0.13642
57.65900 0.49762 0.13700
57.90334 0.49644 0.13767
58.15493 0.49582 0.13804
58.41196 0.49414 0.13900
58.67080 0.49334 0.13946
58.92964 0.49230 0.14006
59.19752 0.49150 0.14052
59.46904 0.49087 0.14088
59.74779 0.48987 0.14146
60.01750 0.48895 0.14199
60.30349 0.48781 0.14265
60.57500 0.48681 0.14323
60.84832 0.48576 0.14383
61.12345 0.48488 0.14434
61.39315 0.48337 0.14521
61.66286 0.48266 0.14562
61.93798 0.48165 0.14620
62.21311 0.48031 0.14697
62.48280 0.47927 0.14757
62.76335 0.47784 0.14839
63.04209 0.47713 0.14880
63.33169 0.47591 0.14950
63.60140 0.47474 0.15018
63.87833 0.47327 0.15102
64.17155 0.47256 0.15144
64.46116 0.47156 0.15201
64.73990 0.47034 0.15272
65.02407 0.46934 0.15329
65.31549 0.46829 0.15390
65.59605 0.46766 0.15426
65.88024 0.46670 0.15482
67.50929 0.46385 0.15646
67.76262 0.45714 0.16032
68.05223 0.46133 0.15791
68.37811 0.45924 0.15911
68.74011 0.45798 0.15984
69.01166 0.45840 0.15960
69.22886 0.45379 0.16225
69.60893 0.45253 0.16298
69.97094 0.45254 0.16298
70.20621 0.45002 0.16443
70.44148 0.45295 0.16274